

<mujoco>
    <worldbody>
        <body name="robot0:ffknuckle" pos="-0.00135 0.03919 0.13556" euler = "-0.0395 0 0">
            <geom name="x" fromto="0 0 0 0.1 0 0" type="capsule" size="0.001 0.01" rgba = "1 0 0 1" contype="0" conaffinity="0"/>
            <geom name="y" fromto="0 0 0 0 0.1 0" type="capsule" size="0.001 0.01" rgba = "0 1 0 1" contype="0" conaffinity="0"/>
            <geom name="z" fromto="0 0 0 0 0 0.1" type="capsule" size="0.001 0.01" rgba = "0 0 1 1" contype="0" conaffinity="0"/>
            <body name="robot0:ffproximal" pos="0 0 0">
                <joint name="robot0:FFJ2" type="hinge" pos="0 0 0" axis="0 1 0" range="0 1.571" damping="0.1"></joint>
                <geom name="robot0:C_ffproximal" type="capsule" pos="0 0 0.02" size="0.0075 0.02"></geom>                         
                <body name="robot0:ffmiddle" pos="0 0 0.046">
                    <joint name="robot0:FFJ1" type="hinge" pos="0 0 0" axis="0 1 0" range="0 1.571"  damping="0.1"></joint>
                    <geom name="robot0:C_ffmiddle" type="capsule" pos="0 0 0.009" size="0.007 0.008"></geom>
                    <body name="robot0:ffdistal" pos="0 0 0.023">
                        <joint name="robot0:FFJ0" type="hinge" pos="0 0 0" axis="0 1 0" range="0 1.571"  damping="0.1"></joint>
                        <geom name="robot0:C_ffdistal" type="capsule" pos="0 0 0.01" size="0.0055 0.01"></geom>
                    </body>
                </body>
            </body>
        </body>   
    </worldbody>
    <tendon>
		<fixed name="robot0:T_FFJ2c" limited="true" range="-0.0001 0.0001" solreflimit="0.002 0.1" >
            <joint joint="robot0:FFJ2" coef="0.003996"></joint>
            <joint joint="robot0:FFJ0" coef="-0.005806"></joint>
        </fixed>
        <!-- <fixed name="robot0:T_FFJ2u" limited="true" range="-0.007 0.03" solreflimit="0.002 0.1" >
            <joint joint="robot0:FFJ2" coef="0.003996"></joint>
            <joint joint="robot0:FFJ0" coef="0.005806"></joint>
        </fixed> -->
        <!-- <fixed name="robot0:T_FFJ2d" limited="true" range="-0.03 0.007" solreflimit="0.002 0.1" >
            <joint joint="robot0:FFJ2" coef="-0.003996"></joint>
            <joint joint="robot0:FFJ0" coef="-0.005806"></joint>
        </fixed> -->
        <fixed name="robot0:T_FFJ1c" limited="true" range="-0.0001 0.0001" solreflimit="0.002 0.1" >
            <joint joint="robot0:FFJ2" coef="0.007094"></joint>
            <joint joint="robot0:FFJ1" coef="-0.005806"></joint>
        </fixed>
        <!-- <fixed name="robot0:T_FFJ1u" limited="true" range="-0.007 0.03" solreflimit="0.002 0.1" >
            <joint joint="robot0:FFJ2" coef="0.007094"></joint>
            <joint joint="robot0:FFJ1" coef="0.005806"></joint>
        </fixed>
        <fixed name="robot0:T_FFJ1d" limited="true" range="-0.03 0.007" solreflimit="0.002 0.1" >
            <joint joint="robot0:FFJ2" coef="-0.007094"></joint>
            <joint joint="robot0:FFJ1" coef="-0.005806"></joint>
        </fixed> -->
    </tendon>
    <actuator>
        <position name="robot0:A_FFJ2" joint="robot0:FFJ2" ctrllimited="true" ctrlrange="0 1.571" kp="3" forcerange="-10 10"></position>
    </actuator>
</mujoco>



<!-- <mujoco model="test">
    <compiler coordinate="global"/>
    <default>
        <geom rgba=".9 .7 .1 1" size="0.01"/>
        <site type="sphere" rgba=".9 .9 .9 1" size="0.005"/>
        <joint type="hinge" axis="0 1 0" limited="true" range="0 60" solimplimit="0.95 0.95 0.1"/>
    </default>
    <visual>
    <headlight diffuse=".7 .7 .7"/>
    </visual>
    <worldbody>
        <body>
            <geom type="cylinder" fromto="-0.03 0 0.2 -0.03 0 0.15" size="0.03" rgba=".2 .2 .5 1" density="5000"/>
            <joint type="slide" pos="-0.03 0 0.2" axis="0 0 1" limited="false"/>
            <site name="s1" pos="-0.03 0 0.2"/>
        </body>
        <site name="s2" pos="-0.03 0 0.32"/>
        <body>
            <geom type="capsule" fromto="0 0 0.3 0.1 0 0.3"/>
            <geom name="g1" type="cylinder" fromto="0.0 0.015 0.3 0.0 -0.015 0.3" size="0.02" rgba=".3 .9 .3 .4"/>
            <joint pos="0 0 0.3"/>
            <site name="s3" pos="0.02 0 0.32"/>
            <body>
                <geom type="capsule" fromto="0.1 0 0.3 0.2 0 0.3"/>
                <geom name="g2" type="cylinder" fromto="0.1 0.015 0.3 0.1 -0.015 0.3" size="0.02" rgba=".3 .9 .3 .4"/>
                <joint pos="0.1 0 0.3"/>
                <site name="s4" pos="0.13 0 0.31"/>
                <site name="s5" pos="0.15 0 0.32"/>
                <site name="side2" pos="0.1 0 0.33"/>
                <body>
                    <geom type="capsule" fromto="0.2 0 0.3 0.27 0 0.3"/>
                    <geom name="g3" type="cylinder" fromto="0.2 0.015 0.3 0.2 -0.015 0.3" size="0.02" rgba=".3 .9 .3 .4"/>
                    <joint pos="0.2 0 0.3"/>
                    <site name="s6" pos="0.23 0 0.31"/>
                    <site name="side3" pos="0.2 0 0.33"/>
                </body>
            </body>
        </body>
        </worldbody>
    <tendon>
        <spatial width="0.002" rgba=".95 .3 .3 1" limited="true" range="0 0.33">
            <site site="s1"/>
            <site site="s2"/>
            <geom geom="g1"/>
            <site site="s3"/>
            <pulley divisor="2"/>
            <site site="s3"/>
            <geom geom="g2" sidesite="side2"/>
            <site site="s4"/>
            <pulley divisor="2"/>
            <site site="s3"/>
            <geom geom="g2" sidesite="side2"/>
            <site site="s5"/>
            <geom geom="g3" sidesite="side3"/>
            <site site="s6"/>
        </spatial>
    </tendon>
</mujoco> -->
